Traceback (most recent call last):
  File "/home2/apai3/ling573/src/random_forest.py", line 72, in <module>
    main(args)
  File "/home2/apai3/ling573/src/random_forest.py", line 55, in main
    dev_acc = rf_classifier.score(dev_feature_vector, dev_labels)
  File "/home2/apai3/anaconda3/envs/573-project/lib/python3.9/site-packages/sklearn/base.py", line 651, in score
    return accuracy_score(y, self.predict(X), sample_weight=sample_weight)
  File "/home2/apai3/anaconda3/envs/573-project/lib/python3.9/site-packages/sklearn/ensemble/_forest.py", line 808, in predict
    proba = self.predict_proba(X)
  File "/home2/apai3/anaconda3/envs/573-project/lib/python3.9/site-packages/sklearn/ensemble/_forest.py", line 850, in predict_proba
    X = self._validate_X_predict(X)
  File "/home2/apai3/anaconda3/envs/573-project/lib/python3.9/site-packages/sklearn/ensemble/_forest.py", line 579, in _validate_X_predict
    X = self._validate_data(X, dtype=DTYPE, accept_sparse="csr", reset=False)
  File "/home2/apai3/anaconda3/envs/573-project/lib/python3.9/site-packages/sklearn/base.py", line 585, in _validate_data
    self._check_n_features(X, reset=reset)
  File "/home2/apai3/anaconda3/envs/573-project/lib/python3.9/site-packages/sklearn/base.py", line 400, in _check_n_features
    raise ValueError(
ValueError: X has 3288 features, but RandomForestClassifier is expecting 10415 features as input.
